Workbook

Sheet Submissions
A1: # | B1: Authors | C1: Title | D1: Decision | E1: CATEGORY | G1: COUNT ON SCHEDULE | I1: CATEGORIES | L1: TALK TYPES
A2: 7 | B2: Lucas English, Sam Roberts, Stephen Bartlett, Andrew Doherty and Dominic Williamson | C2: Ising on the donut: Regimes of topological quantum error correction from statistical mechanics | D2: ACCEPT | E2: COND MAT | G2: =COUNTIF(Schedule!A:G,C2) -> 1 | I2: PRAC DECODER | J2: =COUNTIF(Submissions!E:E,I2) -> 2 | L2: RC ACCEPT | M2: =COUNTIF(Submissions!D:D, L2) -> 8
A3: 108 | B3: Dominic Williamson | C3: Partial Self-Correction in Layer Codes | D3: ACCEPT | E3: COND MAT | G3: =COUNTIF(Schedule!A:G,C3) -> 1 | I3: SIMULATION | J3: =COUNTIF(Submissions!E:E,I3) -> 6 | L3: ACCEPT | M3: =COUNTIF(Submissions!D:D, L3) -> 30
A4: 147 | B4: Naren Manjunath, Vieri Mattei, Apoorv Tiwari and Tyler Ellison | C4: Universal quantum computation with group surface codes | D4: ACCEPT | E4: COND MAT | G4: =COUNTIF(Schedule!A:G,C4) -> 1 | I4: EXP | J4: =COUNTIF(Submissions!E:E,I4) -> 3 | L4: ACCEPT AS MERGED TALK | M4: =COUNTIF(Submissions!D:D, L4) -> 6
A5: 53 | B5: Anasuya Lyons and Benjamin J. Brown | C5: Quantum computing with anyons is fault-tolerant | D5: ACCEPT | E5: CONSTRUCTION | G5: =COUNTIF(Schedule!A:G,C5) -> 1 | I5: QLDPC | J5: =COUNTIF(Submissions!E:E,I5) -> 5
A6: 59 | B6: Lily Wang, Andy Liu, Ray Li, Aleksander Kubica and Shouzhen Gu | C6: Check-weight-constrained quantum codes: Bounds and examples | D6: ACCEPT | E6: CONSTRUCTION | G6: =COUNTIF(Schedule!A:G,C6) -> 1 | I6: MAGIC EXP | J6: =COUNTIF(Submissions!E:E,I6) -> 2 | L6: TOTAL | M6: =SUM(M2:M4) -> 44
A7: 126 | B7: Patrick Birchall, Jacob Bridgeman, Chris Dawson, Terry Farrelly, Ye-Hua Liu, Naomi Nickerson, Mihir Pant, Sam Roberts, Karthik Seetharam and David Tuckett | C7: Macromux: scalable postselection for high-threshold fault-tolerant quantum computation | D7: ACCEPT | E7: CONSTRUCTION | G7: =COUNTIF(Schedule!A:G,C7) -> 1 | I7: MAGIC | J7: =COUNTIF(Submissions!E:E,I7) -> 4
A8: 200 | B8: Oscar Higgott, Hasan Sayginel, Matt McEwen, Craig Gidney, Lei Zhang, Francisco Heras and Johannes Bausch | C8: Over 10x Denser Fault Tolerance using Boundary-Connected Modules | D8: RC ACCEPT | E8: CONSTRUCTION | G8: =COUNTIF(Schedule!A:G,C8) -> 1 | I8: CONSTRUCTION | J8: =COUNTIF(Submissions!E:E,I8) -> 6
A9: 217 | B9: Yunzhe Zheng, Rui Chao, Aleksander Kubica and Adam Paetznick | C9: Fault-Tolerant Quantum Computation with Merged Color Codes | D9: RC ACCEPT | E9: CONSTRUCTION | G9: =COUNTIF(Schedule!A:G,C9) -> 1 | I9: LOG GATES | J9: =COUNTIF(Submissions!E:E,I9) -> 7
A10: 15 | B10: Volodymyr Sivak | C10: Reinforcement Learning Control of Quantum Error Correction | D10: ACCEPT | E10: EXP | G10: =COUNTIF(Schedule!A:G,C10) -> 1 | I10: COND MAT | J10: =COUNTIF(Submissions!E:E,I10) -> 4
A11: 116 | B11: Seok-Hyung Lee, Xanda Kolesnikow, Jun Zen Chen, Evan Hockings, Campbell McLauchlan, Georgia Nixon, Tom Scruby, Stephen Bartlett, Robin Harper and Ben Brown | C11: Scalable quantum error correction tailored for a heavy-hex qubit array | D11: RC ACCEPT | E11: EXP | G11: =COUNTIF(Schedule!A:G,C11) -> 1 | I11: THY DECODER | J11: =COUNTIF(Submissions!E:E,I11) -> 5
A12: 151 | B12: Aharon Brodutch, Evan Dobbs, Gregory Baimetov, Edwin Tham and Nicolas Delfosse | C12: Advantage in distributed quantum computing with slow interconnects, and experiments on a monolithic QPU | D12: ACCEPT | E12: CONSTRUCTION | G12: =COUNTIF(Schedule!A:G,C12) -> 1
A13: 179 | B13: Shival Dasu, Matt DeCross, Andrew Guo, Ali Lavasani, Jan Behrends, Asmae Benhemou, Yi-Hsiang Chen, Karl Mayer, Chris N. Self, Selwyn Simsek, Basudha Srivastava, M. S. Allman, Jake Arkinstall, Justin G. Bohnet, Nathaniel Q. Burdick, J.P. Campora III, Alex Chernoguzov, Samuel F. Cooper, Robert D. Delaney, Joan M. Dreiling, Brian Estey, Caroline Figgatt, Cameron Foltz, John P. Gaebler, Alex Hall, Craig A. Holliman, Ali A. Husain, Akhil Isanaka, Colin J. Kennedy, Yuga Kodama, Nikhil Kotibhaskar, Nathan K. Lysne, Ivaylo S. Madjarov, Michael Mills, Alistair R. Milne, Brian Neyenhuis, Annie J. Park, Anthony Ransford, Adam P. Reed, Steven J. Sanders, Charles H. Baldwin, David Hayes, Ben Criger, Andrew Potter and David Amaro | C13: Computing with many encoded logical qubits beyond break-even | D13: ACCEPT | E13: EXP | G13: =COUNTIF(Schedule!A:G,C13) -> 1 | I13: TOTAL | J13: =SUM(J2:J11) -> 44
A14: 10 | B14: Ryohei Kobayashi, Guanyu Zhu, Po-Shen Hsin, Alison Warman and Sakura Schafer-Nameki | C14: Transversal Gates at Arbitrary Levels of the Clifford Hierarchy in 2D Topological Codes | D14: ACCEPT AS MERGED TALK | E14: LOG GATES | F14: MERGE | G14: =COUNTIF(Schedule!A:G,C14) -> 1
A15: 26 | B15: Aranya Chakraborty and Daniel Gottesman | C15: No-Go Theorem on Fault Tolerant Gadgets for Multiple Logical Qubits | D15: ACCEPT | E15: LOG GATES | G15: =COUNTIF(Schedule!A:G,C15) -> 1
A16: 104 | B16: Qian Xu, Harry Zhou, Dolev Bluvstein, Madelyn Cain, Marcin Kalinowski, John Preskil, Mikhail Lukin and Nishad Maskara | C16: Batched high-rate logical operations for quantum LDPC codes | D16: ACCEPT | E16: LOG GATES | G16: =COUNTIF(Schedule!A:G,C16) -> 1
A17: 112 | B17: Christine Li, John Preskill and Qian Xu | C17: Transversal Dimension Jump for Product qLDPC Codes | D17: ACCEPT AS MERGED TALK | E17: LOG GATES | F17: MERGE | G17: =COUNTIF(Schedule!A:G,C17) -> 1
A18: 134 | B18: Boren Gu, Andy Zeyi Liu, Armanda O. Quintavalle, Qian Xu, Jens Eisert and Joschka Roffe | C18: QGPU: Parallel logic in quantum LDPC codes | D18: ACCEPT | E18: LOG GATES | G18: =COUNTIF(Schedule!A:G,C18) -> 1
A19: 137 | B19: Kathleen Chang, Alexander Cowtan, Zhiyang He, Tomas Jochym-O'Connor, Dominic Williamson, Theodore Yoder and Guanyu Zhu | C19: Constant-Time QLDPC Code Surgery: Formulation and Constructions | D19: ACCEPT | E19: LOG GATES | G19: =COUNTIF(Schedule!A:G,C19) -> 1
A20: 235 | B20: Maine Christos, Chiu-Fan Bowen Lo, Vedika Khemani and Rahul Sahay | C20: Non-Abelian Quantum Low-Density Parity Check Codes and Non-Clifford Operations from Gauging Logical Gates via Measurements | D20: ACCEPT | E20: LOG GATES | G20: =COUNTIF(Schedule!A:G,C20) -> 1
A21: 71 | B21: Louis Golowich, Kathleen Chang and Guanyu Zhu | C21: Constant-Overhead Addressable Gates via Single-Shot Code Switching | D21: ACCEPT AS MERGED TALK | E21: MAGIC | F21: MERGE | G21: =COUNTIF(Schedule!A:G,C21) -> 1
A22: 82 | B22: Varun Menon, J. Pablo Bonilla Ataides, Rohan Mehta, Andi Gu, Daniel Bochen Tan and Mikhail Lukin | C22: Efficient magic-state generation with quantum tricycle codes | D22: ACCEPT | E22: MAGIC | G22: =COUNTIF(Schedule!A:G,C22) -> 1
A23: 199 | B23: Sheng-Jie Huang, Alison Warman, Sakura Schafer-Nameki and Yanzhu Chen | C23: Hybrid Lattice Surgery: Non-Cliﬀord Gates via Non-Abelian Surface Codes | D23: ACCEPT AS MERGED TALK | E23: MAGIC | F23: MERGE | G23: =COUNTIF(Schedule!A:G,C23) -> 1
A24: 232 | B24: Anqi Gong, Christopher Pattison, Patrick Rall and Adam Wills | C24: Magic state distillation via codes over binary extension fields | D24: RC ACCEPT | E24: MAGIC | G24: =COUNTIF(Schedule!A:G,C24) -> 1
A25: 42 | B25: Lucas Daguerre, Robin Blume-Kohout, Natalie C. Brown, David Hayes and Isaac H. Kim | C25: Experimental Demonstration of High-Fidelity Logical Magic States from Code Switching | D25: ACCEPT | E25: MAGIC EXP | G25: =COUNTIF(Schedule!A:G,C25) -> 1
A26: 156 | B26: Emma Rosenfeld, Craig Gidney, Gabrielle Roberts, Alexis Morvan, Nathan Lacroix, Dvir Kafri, Jeffrey Marshall, Ming Li, Volodymyr Sivak, Alexandre Bourassa and Kevin Satzinger | C26: Magic state cultivation on a superconducting quantum processor | D26: ACCEPT | E26: MAGIC EXP | G26: =COUNTIF(Schedule!A:G,C26) -> 1
A27: 101 | B27: Andi Gu, Pablo Bonilla, Mikhail Lukin and Susanne Yelin | C27: Scaling Neural Decoders to Large Codes and Low Error Rates | D27: RC ACCEPT | E27: PRAC DECODER | G27: =COUNTIF(Schedule!A:G,C27) -> 1
A28: 180 | B28: Andrew Senior, Thomas Edlich, Francisco Heras, Lei Zhang, Oscar Higgot, James Spencer, Taylor Applebaum, Sam Blackwell, Justin Ledford, Akvilė Žemgulytė, Augustin Žídek, Noah Shutty, Andrew Cowie, Yin Li, George Holland, Peter Brooks, Charlie Beattie, Michael Newman, Alex Davies, Cody Jones, Sergio Boixo, Hartmut Neven, Pushmeet Kohli and Johannes Bausch | C28: A scalable and real-time neural decoder for topological quantum codes | D28: ACCEPT | E28: PRAC DECODER | G28: =COUNTIF(Schedule!A:G,C28) -> 1
A29: 4 | B29: Shayan Majidy, Jin Ming Koh, Anqi Gong, Andrei Diaconu, Daniel Tan, Alexandra Geim, Michael Gullans, Norman Yao and Mikhail Lukin | C29: Entangling logical qubits without physical operations | D29: ACCEPT | E29: QLDPC | G29: =COUNTIF(Schedule!A:G,C29) -> 1
A30: 38 | B30: Daniel Tan, J. Pablo Bonilla Ataides, Varun Menon, Jin Ming Koh, Andrei Diaconu and Mikhail Lukin | C30: Syndrome Extraction Circuits with Near-Optimal Depths for Practical Quantum Error Correcting Code Families | D30: RC ACCEPT | E30: QLDPC | G30: =COUNTIF(Schedule!A:G,C30) -> 1
A31: 138 | B31: Benjamin Rodatz, Boldizsár Poór and Aleks Kissinger | C31: Fault Tolerance by Construction | D31: ACCEPT | E31: QLDPC | G31: =COUNTIF(Schedule!A:G,C31) -> 1
A32: 207 | B32: Andrew C Yuan, Nouédyn Baspin and Dominic J. Williamson | C32: Quantum Weight Reduction with Layer Codes | D32: ACCEPT | E32: QLDPC | G32: =COUNTIF(Schedule!A:G,C32) -> 1
A33: 227 | B33: Kyle Gulshen and Tali Kaufman | C33: Symmetric Self-Dual Quantum Codes on High Dimensional Expanders | D33: ACCEPT | E33: QLDPC | G33: =COUNTIF(Schedule!A:G,C33) -> 1
A34: 79 | B34: Han Zheng, Chia-Tung Chu, Senrui Chen, Argyris Giannisis Manes, Su-un Lee, Sisi Zhou and Liang Jiang | C34: Efficient learning of logical noise from syndrome data | D34: ACCEPT AS MERGED TALK | E34: SIMULATION | F34: MERGE | G34: =COUNTIF(Schedule!A:G,C34) -> 1
A35: 90 | B35: Michael Beverland, Malcolm Carroll, Andrew Cross and Theodore Yoder | C35: Fail fast: techniques to probe rare events in quantum error correction | D35: ACCEPT | E35: SIMULATION | G35: =COUNTIF(Schedule!A:G,C35) -> 1
A36: 110 | B36: Jordan Hines, Corey Ostrove, Kenneth Rudinger, Stefan Seritan, Kevin Young, Robin Blume-Kohout and Timothy Proctor | C36: Efficient Simulation and Modeling of Quantum Error Correction with Small Markovian Errors | D36: RC ACCEPT | E36: SIMULATION | G36: =COUNTIF(Schedule!A:G,C36) -> 1
A37: 118 | B37: Kento Tsubouchi, Hyukgun Kwon, Liang Jiang and Nobuyuki Yoshioka | C37: Quantum advantages for syndrome-aware noisy logical observable estimation | D37: ACCEPT AS MERGED TALK | E37: SIMULATION | F37: MERGE | G37: =COUNTIF(Schedule!A:G,C37) -> 1
A38: 210 | B38: Nicola Pancotti and Krysta Svore | C38: Exact learning of quantum noise with tensor networks | D38: RC ACCEPT | E38: SIMULATION | G38: =COUNTIF(Schedule!A:G,C38) -> 1
A39: 259 | B39: Xiao Xiao, Dominik Hangleiter, Dolev Bluvstein, Mikhail Lukin and Michael Gullans | C39: In-situ benchmarking of fault-tolerant quantum circuits | D39: ACCEPT | E39: SIMULATION | G39: =COUNTIF(Schedule!A:G,C39) -> 1
A40: 30 | B40: Satoshi Yoshida, Ethan Lake and Hayata Yamasaki | C40: Proof of a finite threshold for the union-find decoder | D40: ACCEPT | E40: THY DECODER | G40: =COUNTIF(Schedule!A:G,C40) -> 1
...

Sheet Schedule
A1: SCHEDULE | B1: 7th | C1: 8th | D1: 9th | E1: 10th | F1: 11th | G1: 12th
B2: Sunday | C2: Monday | D2: Tuesday | E2: Wednesday | F2: Thursday | G2: Friday
A3: 0.33333333
A4: 0.34375
A5: 0.35416667
A6: 0.36458333 | C6: Opening Remarks
A7: 0.375 | B7: Tutorial | C7: Invited Keynote | D7: Invited Keynote | E7: Invited Keynote | F7: Invited Keynote | G7: Invited Keynote
A8: 0.38541667 | C8: Yue Wu | D8: Leverrier | E8: Thaddeus | F8: Natalie | G8: Khemani
A9: 0.39583333 | C9: 45+15 | D9: 45+15 | E9: 45+15 | F9: 45+15 | G9: 45+15
A10: 0.40625
A11: 0.41666667 | C11: Scaling Neural Decoders to Large Codes and Low Error Rates | D11: Fault Tolerance by Construction | E11: Magic state cultivation on a superconducting quantum processor | F11: QGPU: Parallel logic in quantum LDPC codes | G11: Universal quantum computation with group surface codes
A12: 0.42708333 | C12: RC TALK
A13: 0.4375 | C13: A scalable and real-time neural decoder for topological quantum codes | D13: Symmetric Self-Dual Quantum Codes on High Dimensional Expanders | E13: Experimental Demonstration of High-Fidelity Logical Magic States from Code Switching | F13: Batched high-rate logical operations for quantum LDPC codes | G13: Ising on the donut: Regimes of topological quantum error correction from statistical mechanics
A14: 0.44791667
A15: 0.45833333 | B15: Tutorial | E15: Coffee
A16: 0.46875
A17: 0.47916667 | C17: Proof of a finite threshold for the union-find decoder | D17: Syndrome Extraction Circuits with Near-Optimal Depths for Practical Quantum Error Correcting Code Families | E17: Magic state distillation via codes over binary extension fields | F17: No-Go Theorem on Fault Tolerant Gadgets for Multiple Logical Qubits | G17: Exact learning of quantum noise with tensor networks
A18: 0.48958333 | E18: RC TALK | G18: RC TALK
A19: 0.5 | C19: Minimum Weight Decoding in the Colour Code is NP-hard | D19: Quantum Weight Reduction with Layer Codes | E19: Transversal Gates at Arbitrary Levels of the Clifford Hierarchy in 2D Topological Codes | F19: Constant-Overhead Addressable Gates via Single-Shot Code Switching | G19: Efficient learning of logical noise from syndrome data
A20: 0.51041667 | E20: Hybrid Lattice Surgery: Non-Cliﬀord Gates via Non-Abelian Surface Codes | F20: Transversal Dimension Jump for Product qLDPC Codes | G20: Quantum advantages for syndrome-aware noisy logical observable estimation
A21: 0.52083333 | D21: Group Photo
A22: 0.53125
A23: 0.54166667 | B23: Tutorial | C23: LUNCH | D23: LUNCH | E23: LUNCH | F23: LUNCH | G23: LUNCH
A24: 0.55208333
A25: 0.5625
A26: 0.57291667
A27: 0.58333333 | C27: Reinforcement Learning Control of Quantum Error Correction | D27: Fail fast: techniques to probe rare events in quantum error correction | E27: Advantage in distributed quantum computing with slow interconnects, and experiments on a monolithic QPU | F27: Constant-Time QLDPC Code Surgery: Formulation and Constructions | G27: Linear-Time Encodable and Decodable Quantum Error-Correcting Codes
A28: 0.59375
A29: 0.60416667 | C29: Scalable quantum error correction tailored for a heavy-hex qubit array | D29: Decoding Correlated Errors in Quantum LDPC Codes | E29: Fault-Tolerant Quantum Computation with Merged Color Codes | F29: Non-Abelian Quantum Low-Density Parity Check Codes and Non-Clifford Operations from Gauging Logical Gates via Measurements | G29: Partial Self-Correction in Layer Codes
A30: 0.61458333 | C30: RC TALK | E30: RC TALK
A31: 0.625 | B31: Tutorial | C31: Computing with many encoded logical qubits beyond break-even | D31: Check-weight-constrained quantum codes: Bounds and examples | E31: Over 10x Denser Fault Tolerance using Boundary-Connected Modules | F31: Entangling logical qubits without physical operations | G31: Optimal Decoding with the Worm
A32: 0.63541667 | E32: RC TALK
A33: 0.64583333 | E33: Coffee
A34: 0.65625
A35: 0.66666667 | C35: Efficient Simulation and Modeling of Quantum Error Correction with Small Markovian Errors | D35: Panel | E35: Macromux: scalable postselection for high-threshold fault-tolerant quantum computation | F35: Panel | G35: Quantum computing with anyons is fault-tolerant
A36: 0.67708333 | C36: RC TALK | D36: State of the field | F36: Future of the Field
A37: 0.6875 | C37: In-situ benchmarking of fault-tolerant quantum circuits | E37: Efficient magic-state generation with quantum tricycle codes | G37: Efficient high-threshold decoding for concatenated quantum Hamming codes with near-optimal effective distance
A38: 0.69791667
A39: 0.70833333 | D39: Poster Session | E39: Business | F39: Poster Session | G39: Closing
A40: 0.71875 | E40: Meeting | G40: Remarks
...
